Workbook

Sheet Instructions
B2: Private Cloud Cost Information Gathering Worksheet
B3: Input template for VMware Aria Operations / Cloud Economics cost modeling
B5: PURPOSE
B6: This worksheet captures the monthly infrastructure cost data required to produce an accurate private-cloud cost model. Each section aligns to a cost driver (Server Hardware, Storage, License, Applications, Maintenance, Labor, Network, Facilities, Additional Cost). Complete every applicable section; leave items that do not apply to your environment blank.
B8: HOW TO USE THIS WORKBOOK
B9: Step 1 — Pick your scope | C9: Decide how you will enter data. Option A: treat every datacenter as one aggregate entity and enter unified costs on the 'All Datacenters' tab (fastest). Option B: capture each datacenter separately by copying the 'Reference Template' tab once per site.
B10: Step 2 — Copy the template (Option B only) | C10: Right-click the 'Reference Template' tab → 'Move or Copy' → check 'Create a copy' → rename the new tab to the datacenter name (e.g., 'DC-Ashburn', 'DC-Denver'). A pre-built 'Datacenter-1' tab is included as an example.
B11: Step 3 — Choose a data-entry method per section | C11: Every cost driver offers a fast 'Aggregate/Average' method and a detailed 'Granular' method. Select ONE method per section using the dropdown; only fill in the matching input block.
B12: Step 4 — Enter data in the yellow cells only | C12: Yellow cells are inputs. Black cells contain formulas and will calculate automatically. Do not type over black cells.
B13: Step 5 — Review the Summary tab | C13: The Summary tab rolls up totals across all datacenter tabs. Verify totals match your expectations before returning the workbook.
B15: CELL COLOR LEGEND
B16: Yellow + Blue text | C16: Input cell — type your value here
B17: White + Black text | C17: Formula — calculated automatically, do not edit
B18: White + Green text | C18: Cross-sheet link — pulls from another tab
B19: Green | C19: Method selector — choose ONE option per section
B20: Light orange | C20: Guidance / note — not a data entry field
B22: ALL DATACENTERS vs. PER-DATACENTER — WHICH TO USE?
B23: Use ALL DATACENTERS if… | C23: Use PER-DATACENTER if…
B24: • Costs are contracted/budgeted centrally and not broken out by site • Sites are similar in size, hardware, and role • You need a fast first-pass estimate • You do not need site-level chargeback | C24: • Sites have materially different hardware, labor rates, or facilities costs • You need site-level reporting or chargeback • Datacenters are in different geographies (power, labor, real estate differ) • Auditors/stakeholders require per-site granularity
B26: TAB INDEX
B27: Instructions | C27: You are here. Overview and usage guide.
B28: Reference Template | C28: Blank master template. Copy this tab once per datacenter.
B29: All Datacenters | C29: Use this tab if entering unified costs for all sites combined.
B30: Datacenter-1 | C30: Example of a completed per-datacenter tab. Rename or duplicate as needed.
B31: Summary | C31: Automatic roll-up of totals from all datacenter tabs.
B33: WHO HOLDS THE DATA? (QUICK REFERENCE)
B34: Each section of this workbook includes a 'Typical Source' note identifying the role or office that usually owns the data. Your Points of Contact may vary — use these as a starting point for who to ask within your organization.

Sheet Reference Template
B2: Cost Data Entry — Reference Template (copy me for each datacenter)
B4: Datacenter / Scope Name: | C4: Reference Template (copy me for each datacenter) | H4: Completed By / Date:
B5: Currency: | C5: USD
B6: Reporting Period: | C6: Monthly
B7: Data-entry Mode: | C7: Edit for Specific Datacenter
B10: 1. SERVER HARDWARE
B11: Capture the monthly amortized cost of traditional (3-tier) and/or hyper-converged servers. Choose an averaging method OR itemize by individual server.
B12: Data-Entry Method (choose one): | C12: Average cost for all servers | F12: Typical Source / POC: | G12: IT Asset Management, Contracting / Procurement Office, CIO/CTO office, or Finance (depreciation schedule).
B14: Option A — Average Cost (fastest)
B15: Server Type | C15: # of Servers | D15: Avg. Purchase Cost ($) | E15: Amortization Period (months) | F15: Monthly Cost / Server ($) | G15: Monthly Cost — Subtotal ($) | H15: Notes
B16: Traditional (3-tier) | E16: 60 | F16: =IFERROR(D16/E16,0) -> 0 | G16: =C16*F16 -> 0
B17: Hyper-Converged (HCI) | E17: 60 | F17: =IFERROR(D17/E17,0) -> 0 | G17: =C17*F17 -> 0
B18: Option A Subtotal (Monthly): | G18: =SUM(G16:G17) -> 0
B20: Option B — Granular Per-Server (most accurate)
B21: Server Name / Tag | C21: Type (Trad/HCI) | D21: Purchase Cost ($) | E21: Amortization (months) | F21: Monthly Cost ($) | H21: Notes
F22: =IF(AND(ISNUMBER(D22),ISNUMBER(E22),E22>0),D22/E22,"")
F23: =IF(AND(ISNUMBER(D23),ISNUMBER(E23),E23>0),D23/E23,"")
F24: =IF(AND(ISNUMBER(D24),ISNUMBER(E24),E24>0),D24/E24,"")
F25: =IF(AND(ISNUMBER(D25),ISNUMBER(E25),E25>0),D25/E25,"")
F26: =IF(AND(ISNUMBER(D26),ISNUMBER(E26),E26>0),D26/E26,"")
F27: =IF(AND(ISNUMBER(D27),ISNUMBER(E27),E27>0),D27/E27,"")
F28: =IF(AND(ISNUMBER(D28),ISNUMBER(E28),E28>0),D28/E28,"")
F29: =IF(AND(ISNUMBER(D29),ISNUMBER(E29),E29>0),D29/E29,"")
F30: =IF(AND(ISNUMBER(D30),ISNUMBER(E30),E30>0),D30/E30,"")
F31: =IF(AND(ISNUMBER(D31),ISNUMBER(E31),E31>0),D31/E31,"")
B32: Option B Subtotal (Monthly): | F32: =IFERROR(SUM(F22:F31),0) -> 0
B34: SERVER HARDWARE — Monthly Total ($): | H34: =IF(C12="Average cost for all servers",G18,F32) -> 0
B36: 2. STORAGE
B37: Dedicated storage arrays, SAN/NAS, or external storage (exclude HCI-integrated vSAN-style storage counted under Server Hardware).
B38: Data-Entry Method (choose one): | C38: Average cost for all storage systems | F38: Typical Source / POC: | G38: Storage Team, IT Asset Management, Contracting / Procurement, Finance (capital lease schedules).
B40: Option A — Average Cost
B41: Storage Tier | C41: # of Arrays | D41: Avg. Cost ($) | E41: Amortization (months) | F41: Monthly / Array ($) | G41: Subtotal ($) | H41: Notes
B42: All-Flash | E42: 60 | F42: =IFERROR(D42/E42,0) -> 0 | G42: =C42*F42 -> 0
B43: Hybrid/Disk | E43: 60 | F43: =IFERROR(D43/E43,0) -> 0 | G43: =C43*F43 -> 0
B44: Archive/Backup | E44: 60 | F44: =IFERROR(D44/E44,0) -> 0 | G44: =C44*F44 -> 0
B45: Option A Subtotal: | G45: =SUM(G42:G44) -> 0
B47: Option B — Granular Per-Array
B48: Array Name / Tag | C48: Tier | D48: Cost ($) | E48: Amortization (months) | F48: Monthly Cost ($) | H48: Notes
F49: =IF(AND(ISNUMBER(D49),ISNUMBER(E49),E49>0),D49/E49,"")
F50: =IF(AND(ISNUMBER(D50),ISNUMBER(E50),E50>0),D50/E50,"")
...

Sheet All Datacenters
B2: Cost Data Entry — All Datacenters (aggregate)
B4: Datacenter / Scope Name: | C4: All Datacenters (aggregate) | H4: Completed By / Date:
B5: Currency: | C5: USD
B6: Reporting Period: | C6: Monthly
B7: Data-entry Mode: | C7: Edit for All Datacenters
B9: 1. SERVER HARDWARE
B10: Capture the monthly amortized cost of traditional (3-tier) and/or hyper-converged servers. Choose an averaging method OR itemize by individual server.
B11: Data-Entry Method (choose one): | C11: Average cost for all servers | F11: Typical Source / POC: | G11: IT Asset Management, Contracting / Procurement Office, CIO/CTO office, or Finance (depreciation schedule).
B13: Option A — Average Cost (fastest)
B14: Server Type | C14: # of Servers | D14: Avg. Purchase Cost ($) | E14: Amortization Period (months) | F14: Monthly Cost / Server ($) | G14: Monthly Cost — Subtotal ($) | H14: Notes
B15: Traditional (3-tier) | C15: 0 | D15: 0 | E15: 60 | F15: =IFERROR(D15/E15,0) -> 0 | G15: =C15*F15 -> 0
B16: Hyper-Converged (HCI) | E16: 60 | F16: =IFERROR(D16/E16,0) -> 0 | G16: =C16*F16 -> 0
B17: Option A Subtotal (Monthly): | G17: =SUM(G15:G16) -> 0
B19: Option B — Granular Per-Server (most accurate)
B20: Server Name / Tag | C20: Type (Trad/HCI) | D20: Purchase Cost ($) | E20: Amortization (months) | F20: Monthly Cost ($) | H20: Notes
F21: =IF(AND(ISNUMBER(D21),ISNUMBER(E21),E21>0),D21/E21,"")
F22: =IF(AND(ISNUMBER(D22),ISNUMBER(E22),E22>0),D22/E22,"")
F23: =IF(AND(ISNUMBER(D23),ISNUMBER(E23),E23>0),D23/E23,"")
F24: =IF(AND(ISNUMBER(D24),ISNUMBER(E24),E24>0),D24/E24,"")
F25: =IF(AND(ISNUMBER(D25),ISNUMBER(E25),E25>0),D25/E25,"")
F26: =IF(AND(ISNUMBER(D26),ISNUMBER(E26),E26>0),D26/E26,"")
F27: =IF(AND(ISNUMBER(D27),ISNUMBER(E27),E27>0),D27/E27,"")
F28: =IF(AND(ISNUMBER(D28),ISNUMBER(E28),E28>0),D28/E28,"")
F29: =IF(AND(ISNUMBER(D29),ISNUMBER(E29),E29>0),D29/E29,"")
F30: =IF(AND(ISNUMBER(D30),ISNUMBER(E30),E30>0),D30/E30,"")
F31: =IFERROR(SUM(F21:F30),0) -> 0
B33: SERVER HARDWARE — Monthly Total ($): | H33: =IF(C11="Average cost for all servers",G17,F31) -> 0
B35: 2. STORAGE
B36: Dedicated storage arrays, SAN/NAS, or external storage (exclude HCI-integrated vSAN-style storage counted under Server Hardware).
B37: Data-Entry Method (choose one): | C37: Average cost for all storage systems | F37: Typical Source / POC: | G37: Storage Team, IT Asset Management, Contracting / Procurement, Finance (capital lease schedules).
B39: Option A — Average Cost
B40: Storage Tier | C40: # of Arrays | D40: Avg. Cost ($) | E40: Amortization (months) | F40: Monthly / Array ($) | G40: Subtotal ($) | H40: Notes
B41: All-Flash | C41: 0 | D41: 0 | E41: 60 | F41: =IFERROR(D41/E41,0) -> 0 | G41: =C41*F41 -> 0
B42: Hybrid/Disk | E42: 60 | F42: =IFERROR(D42/E42,0) -> 0 | G42: =C42*F42 -> 0
B43: Archive/Backup | E43: 60 | F43: =IFERROR(D43/E43,0) -> 0 | G43: =C43*F43 -> 0
B44: Option A Subtotal: | G44: =SUM(G41:G43) -> 0
B46: Option B — Granular Per-Array
B47: Array Name / Tag | C47: Tier | D47: Cost ($) | E47: Amortization (months) | F47: Monthly Cost ($) | H47: Notes
F48: =IF(AND(ISNUMBER(D48),ISNUMBER(E48),E48>0),D48/E48,"")
F49: =IF(AND(ISNUMBER(D49),ISNUMBER(E49),E49>0),D49/E49,"")
...

Sheet Datacenter-1
B2: Cost Data Entry — Datacenter-1
B4: Datacenter / Scope Name: | C4: Datacenter-1 | H4: Completed By / Date:
B5: Currency: | C5: USD
B6: Reporting Period: | C6: Monthly
B7: Data-entry Mode: | C7: Edit for Specific Datacenter
B10: 1. SERVER HARDWARE
B11: Capture the monthly amortized cost of traditional (3-tier) and/or hyper-converged servers. Choose an averaging method OR itemize by individual server.
B12: Data-Entry Method (choose one): | C12: Average cost for all servers | F12: Typical Source / POC: | G12: IT Asset Management, Contracting / Procurement Office, CIO/CTO office, or Finance (depreciation schedule).
B14: Option A — Average Cost (fastest)
B15: Server Type | C15: # of Servers | D15: Avg. Purchase Cost ($) | E15: Amortization Period (months) | F15: Monthly Cost / Server ($) | G15: Monthly Cost — Subtotal ($) | H15: Notes
B16: Traditional (3-tier) | E16: 60 | F16: =IFERROR(D16/E16,0) -> 0 | G16: =C16*F16 -> 0
B17: Hyper-Converged (HCI) | E17: 60 | F17: =IFERROR(D17/E17,0) -> 0 | G17: =C17*F17 -> 0
B18: Option A Subtotal (Monthly): | G18: =SUM(G16:G17) -> 0
B20: Option B — Granular Per-Server (most accurate)
B21: Server Name / Tag | C21: Type (Trad/HCI) | D21: Purchase Cost ($) | E21: Amortization (months) | F21: Monthly Cost ($) | H21: Notes
F22: =IF(AND(ISNUMBER(D22),ISNUMBER(E22),E22>0),D22/E22,"")
F23: =IF(AND(ISNUMBER(D23),ISNUMBER(E23),E23>0),D23/E23,"")
F24: =IF(AND(ISNUMBER(D24),ISNUMBER(E24),E24>0),D24/E24,"")
F25: =IF(AND(ISNUMBER(D25),ISNUMBER(E25),E25>0),D25/E25,"")
F26: =IF(AND(ISNUMBER(D26),ISNUMBER(E26),E26>0),D26/E26,"")
F27: =IF(AND(ISNUMBER(D27),ISNUMBER(E27),E27>0),D27/E27,"")
F28: =IF(AND(ISNUMBER(D28),ISNUMBER(E28),E28>0),D28/E28,"")
F29: =IF(AND(ISNUMBER(D29),ISNUMBER(E29),E29>0),D29/E29,"")
F30: =IF(AND(ISNUMBER(D30),ISNUMBER(E30),E30>0),D30/E30,"")
F31: =IF(AND(ISNUMBER(D31),ISNUMBER(E31),E31>0),D31/E31,"")
B32: Option B Subtotal (Monthly): | F32: =IFERROR(SUM(F22:F31),0) -> 0
B34: SERVER HARDWARE — Monthly Total ($): | H34: =IF(C12="Average cost for all servers",G18,F32) -> 0
B36: 2. STORAGE
B37: Dedicated storage arrays, SAN/NAS, or external storage (exclude HCI-integrated vSAN-style storage counted under Server Hardware).
B38: Data-Entry Method (choose one): | C38: Average cost for all storage systems | F38: Typical Source / POC: | G38: Storage Team, IT Asset Management, Contracting / Procurement, Finance (capital lease schedules).
B40: Option A — Average Cost
B41: Storage Tier | C41: # of Arrays | D41: Avg. Cost ($) | E41: Amortization (months) | F41: Monthly / Array ($) | G41: Subtotal ($) | H41: Notes
B42: All-Flash | E42: 60 | F42: =IFERROR(D42/E42,0) -> 0 | G42: =C42*F42 -> 0
B43: Hybrid/Disk | E43: 60 | F43: =IFERROR(D43/E43,0) -> 0 | G43: =C43*F43 -> 0
B44: Archive/Backup | E44: 60 | F44: =IFERROR(D44/E44,0) -> 0 | G44: =C44*F44 -> 0
B45: Option A Subtotal: | G45: =SUM(G42:G44) -> 0
B47: Option B — Granular Per-Array
B48: Array Name / Tag | C48: Tier | D48: Cost ($) | E48: Amortization (months) | F48: Monthly Cost ($) | H48: Notes
F49: =IF(AND(ISNUMBER(D49),ISNUMBER(E49),E49>0),D49/E49,"")
F50: =IF(AND(ISNUMBER(D50),ISNUMBER(E50),E50>0),D50/E50,"")
...

Sheet Summary
B2: Summary — Consolidated Private Cloud Costs
B3: Auto-rolled totals from each datacenter tab. Edit data on the source tabs — this view is read-only.
B5: Cost Driver | C5: All Datacenters | D5: Datacenter-1 | E5: Total (All Tabs)
B6: Server Hardware | C6: ='All Datacenters'!H33 -> 0 | D6: ='Datacenter-1'!H34 -> 0 | E6: =SUM(C6:D6) -> 0
B7: Storage | C7: ='All Datacenters'!H56 -> 0 | D7: ='Datacenter-1'!H57 -> 0 | E7: =SUM(C7:D7) -> 0
B8: License | C8: ='All Datacenters'!H87 -> 0 | D8: ='Datacenter-1'!H88 -> 0 | E8: =SUM(C8:D8) -> 0
B9: Applications | C9: ='All Datacenters'!H112 -> 0 | D9: ='Datacenter-1'!H113 -> 0 | E9: =SUM(C9:D9) -> 0
B10: Maintenance | C10: ='All Datacenters'!H127 -> 0 | D10: ='Datacenter-1'!H128 -> 0 | E10: =SUM(C10:D10) -> 0
B11: Labor | C11: ='All Datacenters'!H143 -> 0 | D11: ='Datacenter-1'!H144 -> 0 | E11: =SUM(C11:D11) -> 0
B12: Network | C12: ='All Datacenters'!H161 -> 0 | D12: ='Datacenter-1'!H162 -> 0 | E12: =SUM(C12:D12) -> 0
B13: Facilities | C13: ='All Datacenters'!H176 -> 0 | D13: ='Datacenter-1'!H177 -> 0 | E13: =SUM(C13:D13) -> 0
B14: Additional Cost | C14: ='All Datacenters'!H194 -> 0 | D14: ='Datacenter-1'!H195 -> 0 | E14: =SUM(C14:D14) -> 0
B15: MONTHLY GRAND TOTAL | C15: ='All Datacenters'!H198 -> 0 | D15: ='Datacenter-1'!H199 -> 0 | E15: =SUM(C15:D15) -> 0
B16: ANNUAL GRAND TOTAL | C16: =C15*12 -> 0 | D16: =D15*12 -> 0 | E16: =E15*12 -> 0
B19: HOW TO ADD A NEW DATACENTER TAB
B20: 1. Right-click the 'Reference Template' tab → 'Move or Copy' → check 'Create a copy' → OK. 2. Rename the new tab (e.g., 'DC-Ashburn'). 3. Update the 'Datacenter / Scope Name' field at the top of the new tab. 4. To include the new tab in this Summary, add a column: copy an existing column's formulas and update the sheet-name reference. Alternatively, ask your Anthropic / delivery contact to re-run the worksheet generator with the additional tab.
